<?xml version='1.0'?>
<sdf version='1.5'>
  <model name='ductedfan'>
    <pose>0 0 0.35 0 0 0</pose>
    <link name='base_link'>
      <inertial>
        <mass>1.51082</mass>
        <inertia>
          <ixx>0.0276508</ixx>
          <ixy>0</ixy>
          <ixz>0.00026669</ixz>
          <iyy>0.0275263</iyy>
          <iyz>0.00028741</iyz>
          <izz>0.00619679</izz>
        </inertia>
        <pose>-4.1e-05 -7.6e-05 0.042069 0 -0 0</pose>
      </inertial>

      <visual name='visual'>
        <pose>0 0 0 0 -0 0</pose>
        <geometry>
          <mesh>
            <uri>/home/mch/gazebo/models/ductedfan/meshes/base_link.STL</uri>
            <scale>1 1 1</scale>
          </mesh>
        </geometry>        
      </visual>
      <collision name='collision'>
        <laser_retro>0</laser_retro>
        <max_contacts>10</max_contacts>
        <pose>0 0 0 0 -0 0</pose>
        <geometry>
          <mesh>
            <uri>/home/mch/gazebo/models/ductedfan/meshes/base_link.STL</uri>
            <scale>1 1 1</scale>
          </mesh>
        </geometry>        
      </collision>
    </link>
    <link name='csroll'>
      <inertial>
        <mass>0.138453</mass>
        <inertia>
          <ixx>9.877e-05</ixx>
          <ixy>0</ixy>
          <ixz>0</ixz>
          <iyy>0.00067119</iyy>
          <iyz>0.00068256</iyz>
          <izz>0.00068962</izz>
        </inertia>
        <pose>-4.1e-05 0.000748 -0.207851 0 -0 0</pose>
      </inertial> 
      
      <visual name='visual'>
        <pose>0 0 0 0 -0 0</pose>
        <geometry>
          <mesh>
            <uri>/home/mch/gazebo/models/ductedfan/meshes/c1.STL</uri>
            <scale>1 1 1</scale>
          </mesh>
        </geometry>
      </visual>
      <collision name='collision'>
        <laser_retro>0</laser_retro>
        <max_contacts>10</max_contacts>
        <pose>0 0 0 0 -0 0</pose>
        <geometry>
          <mesh>
            <uri>/home/mch/gazebo/models/ductedfan/meshes/c1.STL</uri>
            <scale>1 1 1</scale>
          </mesh>
        </geometry>
   
      </collision>
    </link>
    <link name='cspitch'>
      <inertial>
        <mass>0.149682</mass>
        <inertia>
          <ixx>0.00066011</ixx>
          <ixy>8.528e-05</ixy>
          <ixz>0.00068962</ixz>
          <iyy>0.166667</iyy>
          <iyz>0</iyz>
          <izz>0.166667</izz>
        </inertia>
        <pose>0.00036 -7.6e-05 -0.208687 0 -0 0</pose>
      </inertial>
     
      <visual name='visual'>
        <pose>0 0 0 0 -0 0</pose>
        <geometry>
          <mesh>
            <uri>/home/mch/gazebo/models/ductedfan/meshes/c2.STL</uri>
            <scale>1 1 1</scale>
          </mesh>
        </geometry>    
      </visual>
      <collision name='collision'>
        <laser_retro>0</laser_retro>
        <max_contacts>10</max_contacts>
        <pose>0 0 0 0 -0 0</pose>
        <geometry>
          <mesh>
            <uri>/home/mch/gazebo/models/ductedfan/meshes/c2.STL</uri>
            <scale>1 1 1</scale>
          </mesh>
        </geometry>
      </collision>
    </link>
    <link name='r1'>
      <inertial>
        <mass>0.015678</mass>
        <inertia>
          <ixx>1.851e-05</ixx>
          <ixy>0</ixy>
          <ixz>0</ixz>
          <iyy>1.855e-05</iyy>
          <iyz>0</iyz>
          <izz>3.648e-05</izz>
        </inertia>
        <pose>0.000403 0.000759 -0.071513 0 -0 0</pose>
      </inertial>
      
      <visual name='visual'>
        <pose>0 0 0 0 -0 0</pose>
        <geometry>
          <mesh>
            <uri>/home/mch/gazebo/models/ductedfan/meshes/r1.STL</uri>
            <scale>1 1 1</scale>
          </mesh>
        </geometry>
     
      </visual>
      <collision name='collision'>
        <laser_retro>0</laser_retro>
        <max_contacts>10</max_contacts>
        <pose>0 0 0 0 -0 0</pose>
        <geometry>
          <mesh>
            <uri>/home/mch/gazebo/models/ductedfan/meshes/r1.STL</uri>
            <scale>1 1 1</scale>
          </mesh>
        </geometry>
      
      </collision>
    </link>
    <link name='r2'>
      <inertial>
        <mass>0.015678</mass>
        <inertia>
          <ixx>1.851e-05</ixx>
          <ixy>0</ixy>
          <ixz>0</ixz>
          <iyy>1.855e-05</iyy>
          <iyz>0</iyz>
          <izz>3.648e-05</izz>
        </inertia>
        <pose>0.000403 0.000759 -0.154513 0 -0 0</pose>
      </inertial>
     
      <visual name='visual'>
        <pose>0 0 0 0 -0 0</pose>
        <geometry>
          <mesh>
            <uri>/home/mch/gazebo/models/ductedfan/meshes/r2.STL</uri>
            <scale>1 1 1</scale>
          </mesh>
        </geometry>
     
      </visual>
      <collision name='collision'>
        <laser_retro>0</laser_retro>
        <max_contacts>10</max_contacts>
        <pose>0 0 0 0 -0 0</pose>
        <geometry>
          <mesh>
            <uri>/home/mch/gazebo/models/ductedfan/meshes/r2.STL</uri>
            <scale>1 1 1</scale>
          </mesh>
        </geometry>
      
      </collision>
    </link>
    <joint name='csroll_joint' type='revolute'>
      <parent>base_link</parent>
      <child>csroll</child>
      <pose>0 0.00074 -0.19763 0 -0 0</pose>
      <axis>
        <xyz>1 0 0</xyz>
        <limit>
          <lower>-0.3491</lower>
          <upper>0.3491</upper>
          <effort>-1</effort>
          <velocity>-1</velocity>
        </limit>
        <dynamics>
          <damping>1.0</damping>
        </dynamics>
      </axis>
      <physics>
        <ode>
          <implicit_spring_damper>1</implicit_spring_damper>
        </ode>
      </physics>
    </joint>
    <joint name='cspitch_joint' type='revolute'>
      <parent>base_link</parent>
      <child>cspitch</child>
      <pose>0.00037 0 -0.19763 0 -0 0</pose>
      <axis>
        <xyz>0 1 0</xyz>
        <limit>
          <lower>-0.3491</lower>
          <upper>0.3491</upper>
          <effort>-1</effort>
          <velocity>-1</velocity>
        </limit>
        <dynamics>
          <damping>1.0</damping>
        </dynamics>
      </axis>
      <physics>
        <ode>
          <implicit_spring_damper>1</implicit_spring_damper>
        </ode>
      </physics>
    </joint>
    <joint name='r1_joint' type='revolute'>
      <parent>base_link</parent>
      <child>r1</child>
      <pose>0.000403 0.000759 -0.071513 0 -0 0</pose>
      <axis>
        <xyz>0 0 -1</xyz>
        <limit>
          <lower>-1e+12</lower>
          <upper>1e+12</upper>
          <effort>-1</effort>
          <velocity>-1</velocity>
        </limit>
        <dynamics>
          <damping>0.001</damping>
        </dynamics>
      </axis>
      <physics>
        <ode>
          <implicit_spring_damper>1</implicit_spring_damper>
        </ode>
      </physics>
    </joint>
    <joint name='r2_joint' type='revolute'>
      <parent>base_link</parent>
      <child>r2</child>
      <pose>0.000403 0.000759 -0.154513 0 -0 0</pose>
      <axis>
        <xyz>0 0 1</xyz>
        <limit>
          <lower>-1e+12</lower>
          <upper>1e+12</upper>
          <effort>-1</effort>
          <velocity>-1</velocity>
        </limit>
        <dynamics>
          <damping>0.001</damping>
        </dynamics>
      </axis>
      <physics>
        <ode>
          <implicit_spring_damper>1</implicit_spring_damper>
        </ode>
      </physics>
    </joint>
    <!-- Plugins for controlling the thrust and control surfaces -->
    <plugin name="ductedfan_control_plugin" filename="libDFPlugin.so">
      <r1>r1_joint</r1>
      <r2>r2_joint</r2>
      <propeller_max_rpm>2000</propeller_max_rpm>
      <csroll>csroll_joint</csroll>
      <cspitch>cspitch_joint</cspitch>
      <propeller_p_gain>0.001</propeller_p_gain>
      <propeller_i_gain>0</propeller_i_gain>
      <propeller_d_gain>0</propeller_d_gain>
      <surfaces_p_gain>0.001</surfaces_p_gain>
      <surfaces_i_gain>0</surfaces_i_gain>
      <surfaces_d_gain>0</surfaces_d_gain>
    </plugin>
    <!--plugin name="r1_1_blade_plugin" filename="libLiftDragPlugin.so">
      <a0>0.4</a0>
      <cla>4.752798721</cla>
      <cda>0.6417112299</cda>
      <cma>0</cma>
      <alpha_stall>1.5</alpha_stall>
      <cla_stall>-3.85</cla_stall>
      <cda_stall>-0.9233984055</cda_stall>
      <cma_stall>0</cma_stall>
      <cp>0.05 0 0</cp>
      <area>0.1</area>
      <air_density>1.2041</air_density>
      <forward>0 -1 0</forward>
      <upward>0 0 1</upward>
      <link_name>r1</link_name>
    </plugin>
    <plugin name="r1_2_blade_plugin" filename="libLiftDragPlugin.so">
      <a0>0.4</a0>
      <cla>4.752798721</cla>
      <cda>0.6417112299</cda>
      <cma>0</cma>
      <alpha_stall>1.5</alpha_stall>
      <cla_stall>-3.85</cla_stall>
      <cda_stall>-0.9233984055</cda_stall>
      <cma_stall>0</cma_stall>
      <cp>-0.025 -0.0433 0</cp>
      <area>0.1</area>
      <air_density>1.2041</air_density>
      <forward>-0.866 0.5 0</forward>
      <upward>0 0 1</upward>
      <link_name>r1</link_name>
    </plugin>
    <plugin name="r1_3_blade_plugin" filename="libLiftDragPlugin.so">
      <a0>0.4</a0>
      <cla>4.752798721</cla>
      <cda>0.6417112299</cda>
      <cma>0</cma>
      <alpha_stall>1.5</alpha_stall>
      <cla_stall>-3.85</cla_stall>
      <cda_stall>-0.9233984055</cda_stall>
      <cma_stall>0</cma_stall>
      <cp>-0.025 0.0433 0</cp>
      <area>0.1</area>
      <air_density>1.2041</air_density>
      <forward>0.866 0.5 0</forward>
      <upward>0 0 1</upward>
      <link_name>r1</link_name>
    </plugin>
    
    <plugin name="r2_1_blade_plugin" filename="libLiftDragPlugin.so">
      <a0>0.4</a0>
      <cla>4.752798721</cla>
      <cda>0.6417112299</cda>
      <cma>0</cma>
      <alpha_stall>1.5</alpha_stall>
      <cla_stall>-3.85</cla_stall>
      <cda_stall>-0.9233984055</cda_stall>
      <cma_stall>0</cma_stall>
      <cp>0.05 0 0</cp>
      <area>0.1</area>
      <air_density>1.2041</air_density>
      <forward>0 1 0</forward>
      <upward>0 0 1</upward>
      <link_name>r2</link_name>
    </plugin>
    <plugin name="r2_2_blade_plugin" filename="libLiftDragPlugin.so">
      <a0>0.4</a0>
      <cla>4.752798721</cla>
      <cda>0.6417112299</cda>
      <cma>0</cma>
      <alpha_stall>1.5</alpha_stall>
      <cla_stall>-3.85</cla_stall>
      <cda_stall>-0.9233984055</cda_stall>
      <cma_stall>0</cma_stall>
      <cp>-0.025 -0.0433 0</cp>
      <area>0.1</area>
      <air_density>1.2041</air_density>
      <forward>0.866 -0.5 0</forward>
      <upward>0 0 1</upward>
      <link_name>r2</link_name>
    </plugin>
    <plugin name="r2_3_blade_plugin" filename="libLiftDragPlugin.so">
      <a0>0.4</a0>
      <cla>4.752798721</cla>
      <cda>0.6417112299</cda>
      <cma>0</cma>
      <alpha_stall>1.5</alpha_stall>
      <cla_stall>-3.85</cla_stall>
      <cda_stall>-0.9233984055</cda_stall>
      <cma_stall>0</cma_stall>
      <cp>-0.025 0.0433 0</cp>
      <area>0.1</area>
      <air_density>1.2041</air_density>
      <forward>-0.866 -0.5 0</forward>
      <upward>0 0 1</upward>
      <link_name>r2</link_name>
    </plugin-->
    
    <!--plugin name="csroll_plugin" filename="libLiftDragPlugin.so">
      <propeller_link_name>r1</propeller_link_name>
      <propeller_joint>r1_joint</propeller_joint>
      <a0>-0.2</a0>
      <cla>4.752798721</cla>
      <cda>0.6417112299</cda>
      <cma>-1.8</cma>
      <alpha_stall>0.6</alpha_stall>
      <cla_stall>-3.85</cla_stall>
      <cda_stall>-0.9233984055</cda_stall>
      <cma_stall>0</cma_stall>
      <cp>0 0 -0.22</cp>
      <area>2.03458</area>
      <air_density>1.2041</air_density>
      <forward>0 0 1</forward>
      <upward>1 0 0</upward>
      <link_name>base_link</link_name>
      <control_joint_name>csroll_joint</control_joint_name>
      <control_joint_rad_to_cl>-4.0</control_joint_rad_to_cl>
    </plugin>
    <plugin name="cspitch_plugin" filename="libLiftDragPlugin.so">
      <propeller_link_name>r1</propeller_link_name>
      <propeller_joint>r1_joint</propeller_joint>
      <a0>0</a0>
      <cla>4.752798721</cla>
      <cda>0.6417112299</cda>
      <cma>-1.8</cma>
      <alpha_stall>0.6</alpha_stall>
      <cla_stall>-3.85</cla_stall>
      <cda_stall>-0.9233984055</cda_stall>
      <cma_stall>0</cma_stall>
      <cp>0 0 -0.22</cp>
      <area>1.5329</area>
      <air_density>1.2041</air_density>
      <forward>0 0 1</forward>
      <upward>0 -1 0</upward>
      <link_name>base_link</link_name>
      <control_joint_name>cspitch_joint</control_joint_name>
      <control_joint_rad_to_cl>4.0</control_joint_rad_to_cl>
    </plugin-->

  </model>
</sdf>
